Loading original images.......................... Completed
Loading segmented images.......................... Completed
len(images_original):  5285
len(images_segmented):  5285
Casting to one-hot encoding... 2019-07-19 09:20:49.661588: I tensorflow/core/common_runtime/gpu/gpu_device.cc:1392] Found device 0 with properties: 
name: GeForce RTX 2080 Ti major: 7 minor: 5 memoryClockRate(GHz): 1.545
pciBusID: 0000:42:00.0
totalMemory: 10.73GiB freeMemory: 10.53GiB
2019-07-19 09:20:49.661912: I tensorflow/core/common_runtime/gpu/gpu_device.cc:1471] Adding visible gpu devices: 0
2019-07-19 09:20:50.003861: I tensorflow/core/common_runtime/gpu/gpu_device.cc:952] Device interconnect StreamExecutor with strength 1 edge matrix:
2019-07-19 09:20:50.003936: I tensorflow/core/common_runtime/gpu/gpu_device.cc:958]      0 
2019-07-19 09:20:50.003953: I tensorflow/core/common_runtime/gpu/gpu_device.cc:971] 0:   N 
2019-07-19 09:20:50.004302: I tensorflow/core/common_runtime/gpu/gpu_device.cc:1084] Created TensorFlow device (/job:localhost/replica:0/task:0/device:GPU:0 with 10174 MB memory) -> physical GPU (device: 0, name: GeForce RTX 2080 Ti, pci bus id: 0000:42:00.0, compute capability: 7.5)
WARNING:tensorflow:From main.py:41: softmax_cross_entropy_with_logits (from tensorflow.python.ops.nn_ops) is deprecated and will be removed in a future version.
Instructions for updating:

Future major versions of TensorFlow will allow gradients to flow
into the labels input on backprop by default.

See @{tf.nn.softmax_cross_entropy_with_logits_v2}.

2019-07-19 09:20:56.992625: I tensorflow/core/common_runtime/gpu/gpu_device.cc:1471] Adding visible gpu devices: 0
2019-07-19 09:20:56.992735: I tensorflow/core/common_runtime/gpu/gpu_device.cc:952] Device interconnect StreamExecutor with strength 1 edge matrix:
2019-07-19 09:20:56.992748: I tensorflow/core/common_runtime/gpu/gpu_device.cc:958]      0 
2019-07-19 09:20:56.992758: I tensorflow/core/common_runtime/gpu/gpu_device.cc:971] 0:   N 
2019-07-19 09:20:56.992935: I tensorflow/core/common_runtime/gpu/gpu_device.cc:1084] Created TensorFlow device (/job:localhost/replica:0/task:0/device:GPU:0 with 10174 MB memory) -> physical GPU (device: 0, name: GeForce RTX 2080 Ti, pci bus id: 0000:42:00.0, compute capability: 7.5)
2019-07-19 09:21:14.345456: E tensorflow/stream_executor/cuda/cuda_blas.cc:647] failed to run cuBLAS routine cublasSgemm_v2: CUBLAS_STATUS_EXECUTION_FAILED
Done
Traceback (most recent call last):
  File "/usr/local/lib/python3.5/dist-packages/tensorflow/python/client/session.py", line 1322, in _do_call
    return fn(*args)
  File "/usr/local/lib/python3.5/dist-packages/tensorflow/python/client/session.py", line 1307, in _run_fn
    options, feed_dict, fetch_list, target_list, run_metadata)
  File "/usr/local/lib/python3.5/dist-packages/tensorflow/python/client/session.py", line 1409, in _call_tf_sessionrun
    run_metadata)
tensorflow.python.framework.errors_impl.InternalError: Blas SGEMM launch failed : m=2097152, n=14, k=32
	 [[Node: output/Conv2D = Conv2D[T=DT_FLOAT, data_format="NHWC", dilations=[1, 1, 1, 1], padding="SAME", strides=[1, 1, 1, 1], use_cudnn_on_gpu=true, _device="/job:localhost/replica:0/task:0/device:GPU:0"](conv2d_17/Relu, output/kernel/read)]]

During handling of the above exception, another exception occurred:

Traceback (most recent call last):
  File "main.py", line 130, in <module>
    train(parser)
  File "main.py", line 73, in train
    model_unet.is_training: True})
  File "/usr/local/lib/python3.5/dist-packages/tensorflow/python/client/session.py", line 900, in run
    run_metadata_ptr)
  File "/usr/local/lib/python3.5/dist-packages/tensorflow/python/client/session.py", line 1135, in _run
    feed_dict_tensor, options, run_metadata)
  File "/usr/local/lib/python3.5/dist-packages/tensorflow/python/client/session.py", line 1316, in _do_run
    run_metadata)
  File "/usr/local/lib/python3.5/dist-packages/tensorflow/python/client/session.py", line 1335, in _do_call
    raise type(e)(node_def, op, message)
tensorflow.python.framework.errors_impl.InternalError: Blas SGEMM launch failed : m=2097152, n=14, k=32
	 [[Node: output/Conv2D = Conv2D[T=DT_FLOAT, data_format="NHWC", dilations=[1, 1, 1, 1], padding="SAME", strides=[1, 1, 1, 1], use_cudnn_on_gpu=true, _device="/job:localhost/replica:0/task:0/device:GPU:0"](conv2d_17/Relu, output/kernel/read)]]

Caused by op 'output/Conv2D', defined at:
  File "main.py", line 130, in <module>
    train(parser)
  File "main.py", line 37, in train
    model_unet = model.UNet(l2_reg=parser.l2reg).model
  File "/home/qiai002/UNet-TF/util/model.py", line 7, in __init__
    self.model = self.create_model(size, l2_reg)
  File "/home/qiai002/UNet-TF/util/model.py", line 54, in create_model
    outputs = UNet.conv(conv_up4_2, filters=ld.DataSet.length_category(), kernel_size=[1, 1], activation=None, name="output")
  File "/home/qiai002/UNet-TF/util/model.py", line 71, in conv
    name=name
  File "/usr/local/lib/python3.5/dist-packages/tensorflow/python/layers/convolutional.py", line 427, in conv2d
    return layer.apply(inputs)
  File "/usr/local/lib/python3.5/dist-packages/tensorflow/python/keras/engine/base_layer.py", line 774, in apply
    return self.__call__(inputs, *args, **kwargs)
  File "/usr/local/lib/python3.5/dist-packages/tensorflow/python/layers/base.py", line 329, in __call__
    outputs = super(Layer, self).__call__(inputs, *args, **kwargs)
  File "/usr/local/lib/python3.5/dist-packages/tensorflow/python/keras/engine/base_layer.py", line 703, in __call__
    outputs = self.call(inputs, *args, **kwargs)
  File "/usr/local/lib/python3.5/dist-packages/tensorflow/python/keras/layers/convolutional.py", line 184, in call
    outputs = self._convolution_op(inputs, self.kernel)
  File "/usr/local/lib/python3.5/dist-packages/tensorflow/python/ops/nn_ops.py", line 868, in __call__
    return self.conv_op(inp, filter)
  File "/usr/local/lib/python3.5/dist-packages/tensorflow/python/ops/nn_ops.py", line 520, in __call__
    return self.call(inp, filter)
  File "/usr/local/lib/python3.5/dist-packages/tensorflow/python/ops/nn_ops.py", line 204, in __call__
    name=self.name)
  File "/usr/local/lib/python3.5/dist-packages/tensorflow/python/ops/gen_nn_ops.py", line 956, in conv2d
    data_format=data_format, dilations=dilations, name=name)
  File "/usr/local/lib/python3.5/dist-packages/tensorflow/python/framework/op_def_library.py", line 787, in _apply_op_helper
    op_def=op_def)
  File "/usr/local/lib/python3.5/dist-packages/tensorflow/python/framework/ops.py", line 3414, in create_op
    op_def=op_def)
  File "/usr/local/lib/python3.5/dist-packages/tensorflow/python/framework/ops.py", line 1740, in __init__
    self._traceback = self._graph._extract_stack()  # pylint: disable=protected-access

InternalError (see above for traceback): Blas SGEMM launch failed : m=2097152, n=14, k=32
	 [[Node: output/Conv2D = Conv2D[T=DT_FLOAT, data_format="NHWC", dilations=[1, 1, 1, 1], padding="SAME", strides=[1, 1, 1, 1], use_cudnn_on_gpu=true, _device="/job:localhost/replica:0/task:0/device:GPU:0"](conv2d_17/Relu, output/kernel/read)]]

